Traceback (most recent call last):
  File "/opt/hostedtoolcache/Python/3.9.19/x64/lib/python3.9/site-packages/jupyter_cache/executors/utils.py", line 58, in single_nb_execution
    executenb(
  File "/opt/hostedtoolcache/Python/3.9.19/x64/lib/python3.9/site-packages/nbclient/client.py", line 1314, in execute
    return NotebookClient(nb=nb, resources=resources, km=km, **kwargs).execute()
  File "/opt/hostedtoolcache/Python/3.9.19/x64/lib/python3.9/site-packages/jupyter_core/utils/__init__.py", line 165, in wrapped
    return loop.run_until_complete(inner)
  File "/opt/hostedtoolcache/Python/3.9.19/x64/lib/python3.9/asyncio/base_events.py", line 647, in run_until_complete
    return future.result()
  File "/opt/hostedtoolcache/Python/3.9.19/x64/lib/python3.9/site-packages/nbclient/client.py", line 709, in async_execute
    await self.async_execute_cell(
  File "/opt/hostedtoolcache/Python/3.9.19/x64/lib/python3.9/site-packages/nbclient/client.py", line 1062, in async_execute_cell
    await self._check_raise_for_error(cell, cell_index, exec_reply)
  File "/opt/hostedtoolcache/Python/3.9.19/x64/lib/python3.9/site-packages/nbclient/client.py", line 918, in _check_raise_for_error
    raise CellExecutionError.from_cell_and_msg(cell, exec_reply_content)
nbclient.exceptions.CellExecutionError: An error occurred while executing the following cell:
------------------
D = np.arange(1,7).reshape(3,2)
I = np.matlib.identity(D.shape[1])

DI = D @ I

print("D = \n", D)
print("I = \n", I)
print("D * I = \n", DI)

I = np.matlib.identity(D.shape[0])

ID = I @ D

print("I = \n", I)
print("I * D = \n", ID)
------------------


[0;31m---------------------------------------------------------------------------[0m
[0;31mAttributeError[0m                            Traceback (most recent call last)
Cell [0;32mIn[18], line 2[0m
[1;32m      1[0m D [38;5;241m=[39m np[38;5;241m.[39marange([38;5;241m1[39m,[38;5;241m7[39m)[38;5;241m.[39mreshape([38;5;241m3[39m,[38;5;241m2[39m)
[0;32m----> 2[0m I [38;5;241m=[39m [43mnp[49m[38;5;241;43m.[39;49m[43mmatlib[49m[38;5;241m.[39midentity(D[38;5;241m.[39mshape[[38;5;241m1[39m])
[1;32m      4[0m DI [38;5;241m=[39m D [38;5;241m@[39m I
[1;32m      6[0m [38;5;28mprint[39m([38;5;124m"[39m[38;5;124mD = [39m[38;5;130;01m\n[39;00m[38;5;124m"[39m, D)

File [0;32m/opt/hostedtoolcache/Python/3.9.19/x64/lib/python3.9/site-packages/numpy/__init__.py:333[0m, in [0;36m__getattr__[0;34m(attr)[0m
[1;32m    330[0m     [38;5;124m"[39m[38;5;124mRemoved in NumPy 1.25.0[39m[38;5;124m"[39m
[1;32m    331[0m     [38;5;28;01mraise[39;00m [38;5;167;01mRuntimeError[39;00m([38;5;124m"[39m[38;5;124mTester was removed in NumPy 1.25.[39m[38;5;124m"[39m)
[0;32m--> 333[0m [38;5;28;01mraise[39;00m [38;5;167;01mAttributeError[39;00m([38;5;124m"[39m[38;5;124mmodule [39m[38;5;132;01m{!r}[39;00m[38;5;124m has no attribute [39m[38;5;124m"[39m
[1;32m    334[0m                      [38;5;124m"[39m[38;5;132;01m{!r}[39;00m[38;5;124m"[39m[38;5;241m.[39mformat([38;5;18m__name__[39m, attr))

[0;31mAttributeError[0m: module 'numpy' has no attribute 'matlib'

