Traceback (most recent call last):
  File "/opt/hostedtoolcache/Python/3.9.22/x64/lib/python3.9/site-packages/jupyter_cache/executors/utils.py", line 58, in single_nb_execution
    executenb(
  File "/opt/hostedtoolcache/Python/3.9.22/x64/lib/python3.9/site-packages/nbclient/client.py", line 1319, in execute
    return NotebookClient(nb=nb, resources=resources, km=km, **kwargs).execute()
  File "/opt/hostedtoolcache/Python/3.9.22/x64/lib/python3.9/site-packages/jupyter_core/utils/__init__.py", line 165, in wrapped
    return loop.run_until_complete(inner)
  File "/opt/hostedtoolcache/Python/3.9.22/x64/lib/python3.9/asyncio/base_events.py", line 647, in run_until_complete
    return future.result()
  File "/opt/hostedtoolcache/Python/3.9.22/x64/lib/python3.9/site-packages/nbclient/client.py", line 709, in async_execute
    await self.async_execute_cell(
  File "/opt/hostedtoolcache/Python/3.9.22/x64/lib/python3.9/site-packages/nbclient/client.py", line 1062, in async_execute_cell
    await self._check_raise_for_error(cell, cell_index, exec_reply)
  File "/opt/hostedtoolcache/Python/3.9.22/x64/lib/python3.9/site-packages/nbclient/client.py", line 918, in _check_raise_for_error
    raise CellExecutionError.from_cell_and_msg(cell, exec_reply_content)
nbclient.exceptions.CellExecutionError: An error occurred while executing the following cell:
------------------
if torch.accelerator.is_available():
    device = torch.accelerator.current_accelerator()
    print(device)
------------------


[0;31m---------------------------------------------------------------------------[0m
[0;31mAttributeError[0m                            Traceback (most recent call last)
Cell [0;32mIn[35], line 1[0m
[0;32m----> 1[0m [38;5;28;01mif[39;00m [43mtorch[49m[38;5;241;43m.[39;49m[43maccelerator[49m[38;5;241m.[39mis_available():
[1;32m      2[0m     device [38;5;241m=[39m torch[38;5;241m.[39maccelerator[38;5;241m.[39mcurrent_accelerator()
[1;32m      3[0m     [38;5;28mprint[39m(device)

File [0;32m/opt/hostedtoolcache/Python/3.9.22/x64/lib/python3.9/site-packages/torch/__init__.py:1938[0m, in [0;36m__getattr__[0;34m(name)[0m
[1;32m   1935[0m     [38;5;28;01mimport[39;00m[38;5;250m [39m[38;5;21;01mimportlib[39;00m
[1;32m   1936[0m     [38;5;28;01mreturn[39;00m importlib[38;5;241m.[39mimport_module([38;5;124mf[39m[38;5;124m"[39m[38;5;124m.[39m[38;5;132;01m{[39;00mname[38;5;132;01m}[39;00m[38;5;124m"[39m, [38;5;18m__name__[39m)
[0;32m-> 1938[0m [38;5;28;01mraise[39;00m [38;5;167;01mAttributeError[39;00m([38;5;124mf[39m[38;5;124m"[39m[38;5;124mmodule [39m[38;5;124m'[39m[38;5;132;01m{[39;00m[38;5;18m__name__[39m[38;5;132;01m}[39;00m[38;5;124m'[39m[38;5;124m has no attribute [39m[38;5;124m'[39m[38;5;132;01m{[39;00mname[38;5;132;01m}[39;00m[38;5;124m'[39m[38;5;124m"[39m)

[0;31mAttributeError[0m: module 'torch' has no attribute 'accelerator'

